2015-11-13 22:11:37,506 Task exception was never retrieved
future: <Task finished coro=<connect_to_peer() done, defined at .\message_types.py:1158> exception=KeyError('80.94.76.7',) created at c:\Anaconda3\lib\asyncio\tasks.py:330>
source_traceback: Object created at (most recent call last):
  File ".\message_types.py", line 1558, in <module>
    loop.run_until_complete(asyncio.wait(tasks_connect+tasks_keep_alive))
  File "c:\Anaconda3\lib\asyncio\base_events.py", line 304, in run_until_complete
    self.run_forever()
  File "c:\Anaconda3\lib\asyncio\base_events.py", line 276, in run_forever
    self._run_once()
  File "c:\Anaconda3\lib\asyncio\base_events.py", line 1164, in _run_once
    handle._run()
  File "c:\Anaconda3\lib\asyncio\events.py", line 120, in _run
    self._callback(*self._args)
  File "c:\Anaconda3\lib\asyncio\tasks.py", line 238, in _step
    result = next(coro)
  File "c:\Anaconda3\lib\asyncio\tasks.py", line 330, in wait
    fs = {async(f, loop=loop) for f in set(fs)}
  File "c:\Anaconda3\lib\asyncio\tasks.py", line 330, in <setcomp>
    fs = {async(f, loop=loop) for f in set(fs)}
Traceback (most recent call last):
  File ".\message_types.py", line 1486, in read_peer
    msg_body = yield from reader.readexactly(self._4bytes_to_int(msg_length))
  File "c:\Anaconda3\lib\asyncio\streams.py", line 482, in readexactly
    raise IncompleteReadError(partial, len(partial) + n)
asyncio.streams.IncompleteReadError: 9 bytes read on a total of 16393 expected bytes

During handling of the above exception, another exception occurred:

Traceback (most recent call last):
  File ".\message_types.py", line 1349, in connect_to_peer
    msg_ident = yield from self.read_peer(rpeer)
  File ".\message_types.py", line 1495, in read_peer
    raise reader.exception()
TypeError: exceptions must derive from BaseException

During handling of the above exception, another exception occurred:

Traceback (most recent call last):
  File "c:\Anaconda3\lib\asyncio\tasks.py", line 238, in _step
    result = next(coro)
  File ".\message_types.py", line 1363, in connect_to_peer
    self.channel_state[rip].state, \
KeyError: '80.94.76.7'
